Workbook

Sheet Resumen
A2: Criterio | B2: #1 | C2: #2 | D2: #3 | E2: Comentario
A3: Mayor TIR esperada | B3: 2 L3H2 | C3: Reus trasteros | D3: Águilas | E3: L3H2 gana en retorno puro, pero con más trabajo, averías y depreciación
A4: Mejor largo plazo riesgo-ajustado | B4: Águilas 35k → vivienda | C4: Reus trasteros | D4: 2 L3H2 | E4: Águilas combina compra barata + creación de equity + salida residencial
A5: Más pasiva / automatizable | B5: Reus trasteros | C5: Águilas vivienda | D5: Tinamus vivienda | E5: Trasteros puede operar sin personal, pero exige ocupación real
A6: Mayor patrimonio absoluto potencial | B6: Tinamus | C6: Águilas | D6: Reus | E6: Tinamus requiere deuda/capital futuro: no comparar su tamaño con inversiones de 45k sin ajustar
A7: Peor riesgo-retorno base | B7: Camper | E7: Estacionalidad + depreciación + siniestros
A9: RANKING RECOMENDADO A 10 AÑOS | B9: Puntuación | C9: Condición crítica | D9: Decisión
A10: 1. Águilas 35k → vivienda | B10: 8.8/10 | C10: Cambio de uso viable y coste total conversión <=15k | D10: MEJOR INVERSIÓN DE LARGO PLAZO BASE
A11: 2. Reus 22k → 11 trasteros | B11: 8.6/10 | C11: Oferta 22k + licencia + caben 11 unidades + renta media >=60€ | D11: MEJOR CASH YIELD INMOBILIARIO
A12: 3. 2 L3H2 alquiler Madrid | B12: 8.2/10 | C12: Ocupación/seguro/siniestros según modelo | D12: MEJOR RETORNO PURO, MAYOR TRABAJO
A13: 4. Tinamus → vivienda | B13: 7.6/10 | C13: Viabilidad cambio de uso + financiación + reforma | D13: MAYOR UPSIDE ABSOLUTO, NO MEJOR EFICIENCIA DE CAPITAL
A14: 5. Camper | B14: 6.4/10 | C14: Ocupación estacional fuerte | D14: NO PRIORIZAR
A15: 6. Local genérico | B15: N/D | C15: Falta modelo de ingresos | D15: NO RANKEABLE
A17: CORRECCIÓN IMPORTANTE — REUS
A18: El modelo anterior usaba 9.240€/año diciendo 90% de ocupación. Eso es matemáticamente 100%: 11 × 70 × 12 = 9.240. A 90% serían 8.316€ si el precio fuese 70€.
A19: Además, mercado actual de Reus muestra 4m² a ~55-60€/mes, 7m² a 65€ y 12m² a 75€. Por eso el caso BASE usa 60€/mes; 70€ queda como optimista.
A21: VEREDICTO | B21: Si el arquitecto confirma Águilas y el cambio completo cabe en ~14,5k, elegiría ÁGUILAS. Si falla esa condición, mi segunda elección sería REUS a 22k. Si tu prioridad es maximizar caja y aceptas operar activamente, L3H2 supera a ambas en TIR.

Sheet Supuestos
A1: COMPARADOR DE INVERSIONES — SUPUESTOS BASE | B1: Valor | C1: Unidad / criterio | D1: Fuente / nota
A2: Capital disponible | B2: 45000 | C2: EUR | D2: 28k SEPE + 12k indemnización + 5k ahorros
A3: Crecimiento rentas base | B3: 0.02 | C3: % | D3: Supuesto prudente
A4: Coste de venta terminal | B4: 0.05 | C4: % | D4: Supuesto de fricción de salida
A6: ÁGUILAS — LOCAL 35K → VIVIENDA | B6: Columna 1 | C6: Columna 2 | D6: Columna 3
A7: Precio compra | B7: 35000 | C7: EUR | D7: Oferta asumida aceptada
A8: ITP Murcia | B8: 0.0775 | C8: % | D8: https://agenciatributaria.carm.es/documents/20632/1675724/TRIBUTOS%2BCEDIDOS%2BY%2BPROPIOS.pdf/be1014f0-3bcb-4759-9cdf-f3a15d80c2be?version=1.0
A9: Notaría + Registro | B9: 1000 | C9: EUR | D9: Estimación
A10: Agencia | B10: 1271 | C10: EUR | D10: Estimación 3% + IVA; sustituir por factura real
A11: Due diligence | B11: 500 | C11: EUR | D11: Estimación
A12: Adaptación inicial IT | B12: 500 | C12: EUR | D12: Local casi listo
A13: Total adquisición | B13: =B7*(1+B8)+B9+B10+B11+B12 -> 40983.5 | C13: EUR | D13: Calculado
A14: Opex local años 1-2 | B14: 900 | C14: EUR/año | D14: IBI + comunidad + seguro + mantenimiento, estimación
A15: Cambio de uso + reforma | B15: 14500 | C15: EUR | D15: Escenario base: poca reforma física, sí proyecto/licencias/legalización
A16: Valor vivienda post-cambio | B16: 82500 | C16: EUR | D16: Hipótesis conservadora frente a comparables actuales
A17: Renta vivienda inicial | B17: 600 | C17: EUR/mes | D17: Base prudente; comparable 60m² reformado anunciado 795 €/mes
A18: Vacancia / impago | B18: 0.05 | C18: % | D18: Supuesto
A19: Mantenimiento variable | B19: 0.08 | C19: % ingresos | D19: Supuesto
A20: Opex fijo vivienda | B20: 900 | C20: EUR/año | D20: IBI + comunidad + seguro + otros
A21: Crecimiento renta | B21: 0.02 | C21: % | D21: Supuesto
A22: Revalorización inmueble | B22: 0.02 | C22: % | D22: Supuesto
A23: Fuente alquiler comparable | D23: https://www.idealista.com/inmueble/111844477/
A25: REUS — 66m² → 11 TRASTEROS | B25: Columna 1 | C25: Columna 2 | D25: Columna 3
A26: Precio oferta | B26: 22000 | C26: EUR | D26: Oferta simulada
A27: ITP Cataluña | B27: 0.1 | C27: % | D27: Tipo general <=600k
A28: Notaría + Registro + gestoría compra | B28: 1450 | C28: EUR | D28: Estimación
A29: Reforma + divisiones + licencias | B29: 17500 | C29: EUR | D29: 11 unidades + instalaciones + seguridad
A30: Software / web / lanzamiento | B30: 850 | C30: EUR | D30: Estimación
A31: Fondo de reserva | B31: 1000 | C31: EUR | D31: Caja inicial
A32: Total all-in | B32: =B26*(1+B27)+B28+B29+B30+B31 -> 45000 | C32: EUR | D32: Calculado
A33: Nº trasteros | B33: 11 | C33: unidades | D33: Hipótesis; validar plano útil y pasillos
A34: Renta base por unidad | B34: 60 | C34: EUR/mes | D34: CORREGIDO: mercado actual 4m² en Reus ~55-60 €/mes; 70€ es optimista
A35: Ocupación año 1 | B35: 0.5 | C35: % | D35: Ramp-up
A36: Ocupación estabilizada | B36: 0.9 | C36: % | D36: Equivale a 9,9 unidades, no 11
A37: Opex año 1 | B37: 2040 | C37: EUR/año | D37: 170 €/mes
A38: Crecimiento renta | B38: 0.02 | C38: % | D38: Supuesto
A39: Crecimiento opex | B39: 0.02 | C39: % | D39: Supuesto
A40: Cap rate terminal | B40: 0.09 | C40: % | D40: Supuesto conservador para micro-storage local
A41: Costes venta terminal | B41: 0.05 | C41: % | D41: Supuesto
A42: Fuente ITP Cataluña | D42: https://atc.gencat.cat/es/tributs/itpajd/tpo/tarifes-tipus/
...

Sheet ROI 10A
A1: COMPARACIÓN HOMOGÉNEA — 10 AÑOS (BASE)
A2: Inversión | B2: CapEx total / inicial | C2: Caja neta año 1 | D2: Caja neta estabilizada | E2: Valor residual año 10 | F2: Caja operativa acumulada 10A | G2: Valor económico total 10A | H2: ROI económico 10A | I2: TIR 10A | J2: Payback solo caja | K2: Riesgo | L2: Lectura
A3: Águilas 35k → vivienda | B3: ='Aguilas 10A'!I13 -> 55483.5 | C3: ='Aguilas 10A'!F4 -> -900 | D3: ='Aguilas 10A'!F6 -> 5364 | E3: ='Aguilas 10A'!H13 -> 96661.899 | F3: ='Aguilas 10A'!G13 -> 44239.046 | G3: =E3+F3 -> 140900.94 | H3: =(G3-B3)/B3 -> 1.5395108 | I3: ='Aguilas 10A'!B15 -> 0.11469281 | J3: >10 años | K3: Medio hasta licencia; bajo-medio después | L3: Mejor equilibrio patrimonio/riesgo si cambio de uso es viable <=15k
A4: Reus 22k → 11 trasteros | B4: ='Reus Trasteros 10A'!I13 -> 45000 | C4: ='Reus Trasteros 10A'!F4 -> 1920 | D4: ='Reus Trasteros 10A'!F5 -> 5047.2 | E4: ='Reus Trasteros 10A'!H13 -> 65706.658 | F4: ='Reus Trasteros 10A'!G13 -> 51153.561 | G4: =E4+F4 -> 116860.22 | H4: =(G4-B4)/B4 -> 1.5968937 | I4: ='Reus Trasteros 10A'!B15 -> 0.12836158 | J4: ~9 años | K4: Medio | L4: Muy buena renta; validar 11 unidades, licencia y demanda real
A5: 2 L3H2 alquiler | B5: =Supuestos!B63 -> 45000 | C5: =Supuestos!B64 -> 10720 | D5: =Supuestos!B64 -> 10720 | E5: =Supuestos!B65 -> 8772 | F5: =Supuestos!B64*10 -> 107200 | G5: =E5+F5 -> 115972 | H5: =(G5-B5)/B5 -> 1.5771556 | I5: ='Vehiculos 10A'!B15 -> 0.20848185 | J5: ~4,2 años | K5: Alto | L5: Mayor TIR esperada, pero es negocio operativo y activo depreciable
A6: Tinamus → vivienda | B6: ='Tinamus 10A'!I13 -> 144400 | C6: ='Tinamus 10A'!F4 -> -1800 | D6: ='Tinamus 10A'!F6 -> 8190 | E6: ='Tinamus 10A'!H13 -> 210898.69 | F6: ='Tinamus 10A'!G13 -> 66694.517 | G6: =E6+F6 -> 277593.21 | H6: =(G6-B6)/B6 -> 0.92239062 | I6: ='Tinamus 10A'!B15 -> 0.073345255 | J6: >10 años | K6: Medio-alto | L6: Gran patrimonio absoluto, pero exige mucho más capital y ejecución
A7: Camper | B7: =Supuestos!B66 -> 45000 | C7: =Supuestos!B67 -> 5730 | D7: =Supuestos!B67 -> 5730 | E7: =Supuestos!B68 -> 11150 | F7: =Supuestos!B67*10 -> 57300 | G7: =E7+F7 -> 68450 | H7: =(G7-B7)/B7 -> 0.52111111 | I7: ='Vehiculos 10A'!B16 -> 0.073878783 | J7: ~7,9 años | K7: Alto / estacional | L7: Peor relación riesgo-retorno del grupo modelado
A8: Local comercial genérico | B8: 115000 | J8: N/D | K8: Alto / depende actividad | L8: No se puede rankear sin cash flow del negocio

Sheet Aguilas 10A
A1: ÁGUILAS 35K → IT 2 AÑOS → CAMBIO DE USO → ALQUILER
A2: Año | B2: Fase | C2: CapEx | D2: Ingresos alquiler | E2: Opex | F2: Flujo operativo neto | G2: Caja operativa acumulada | H2: Valor activo | I2: CapEx acumulado | J2: ROI económico acumulado | K2: Flujo para TIR
A3: 0 | B3: Compra | C3: =-Supuestos!B13 -> -40983.5 | D3: 0 | E3: 0 | F3: 0 | G3: 0 | H3: =Supuestos!B7 -> 35000 | I3: =Supuestos!B13 -> 40983.5 | J3: =(H3+G3-I3)/I3 -> -0.14599778 | K3: =C3 -> -40983.5
A4: 1 | B4: IT / local | C4: 0 | D4: 0 | E4: =-Supuestos!B14 -> -900 | F4: =D4+E4 -> -900 | G4: =F4 -> -900 | H4: =H3*(1+Supuestos!B22) -> 35700 | I4: =I3 -> 40983.5 | J4: =(H4+G4-I4)/I4 -> -0.15087779 | K4: =F4 -> -900
A5: 2 | B5: IT + conversión | C5: =-Supuestos!B15 -> -14500 | D5: 0 | E5: =-Supuestos!B14 -> -900 | F5: =D5+E5 -> -900 | G5: =G4+F5 -> -1800 | H5: =Supuestos!B16 -> 82500 | I5: =I4-C5 -> 55483.5 | J5: =(H5+G5-I5)/I5 -> 0.45448647 | K5: =C5+F5 -> -15400
A6: 3 | B6: Vivienda alquilada | C6: 0 | D6: =Supuestos!B17*12 -> 7200 | E6: =-(D6*Supuestos!B18+D6*Supuestos!B19+Supuestos!B20) -> -1836 | F6: =D6+E6 -> 5364 | G6: =G5+F6 -> 3564 | H6: =H5*(1+Supuestos!B22) -> 84150 | I6: =I5 -> 55483.5 | J6: =(H6+G6-I6)/I6 -> 0.58090243 | K6: =F6 -> 5364
A7: 4 | B7: Vivienda alquilada | C7: 0 | D7: =D6*(1+Supuestos!B21) -> 7344 | E7: =E6*(1+Supuestos!B21) -> -1872.72 | F7: =D7+E7 -> 5471.28 | G7: =G6+F7 -> 9035.28 | H7: =H6*(1+Supuestos!B22) -> 85833 | I7: =I6 -> 55483.5 | J7: =(H7+G7-I7)/I7 -> 0.70984671 | K7: =F7 -> 5471.28
A8: 5 | B8: Vivienda alquilada | C8: 0 | D8: =D7*(1+Supuestos!B21) -> 7490.88 | E8: =E7*(1+Supuestos!B21) -> -1910.1744 | F8: =D8+E8 -> 5580.7056 | G8: =G7+F8 -> 14615.986 | H8: =H7*(1+Supuestos!B22) -> 87549.66 | I8: =I7 -> 55483.5 | J8: =(H8+G8-I8)/I8 -> 0.84136988 | K8: =F8 -> 5580.7056
A9: 6 | B9: Vivienda alquilada | C9: 0 | D9: =D8*(1+Supuestos!B21) -> 7640.6976 | E9: =E8*(1+Supuestos!B21) -> -1948.3779 | F9: =D9+E9 -> 5692.3197 | G9: =G8+F9 -> 20308.305 | H9: =H8*(1+Supuestos!B22) -> 89300.653 | I9: =I8 -> 55483.5 | J9: =(H9+G9-I9)/I9 -> 0.97552351 | K9: =F9 -> 5692.3197
A10: 7 | B10: Vivienda alquilada | C10: 0 | D10: =D9*(1+Supuestos!B21) -> 7793.5116 | E10: =E9*(1+Supuestos!B21) -> -1987.3454 | F10: =D10+E10 -> 5806.1661 | G10: =G9+F10 -> 26114.471 | H10: =H9*(1+Supuestos!B22) -> 91086.666 | I10: =I9 -> 55483.5 | J10: =(H10+G10-I10)/I10 -> 1.1123602 | K10: =F10 -> 5806.1661
A11: 8 | B11: Vivienda alquilada | C11: 0 | D11: =D10*(1+Supuestos!B21) -> 7949.3818 | E11: =E10*(1+Supuestos!B21) -> -2027.0924 | F11: =D11+E11 -> 5922.2894 | G11: =G10+F11 -> 32036.761 | H11: =H10*(1+Supuestos!B22) -> 92908.4 | I11: =I10 -> 55483.5 | J11: =(H11+G11-I11)/I11 -> 1.2519336 | K11: =F11 -> 5922.2894
A12: 9 | B12: Vivienda alquilada | C12: 0 | D12: =D11*(1+Supuestos!B21) -> 8108.3694 | E12: =E11*(1+Supuestos!B21) -> -2067.6342 | F12: =D12+E12 -> 6040.7352 | G12: =G11+F12 -> 38077.496 | H12: =H11*(1+Supuestos!B22) -> 94766.568 | I12: =I11 -> 55483.5 | J12: =(H12+G12-I12)/I12 -> 1.3942986 | K12: =F12 -> 6040.7352
A13: 10 | B13: Vivienda alquilada | C13: 0 | D13: =D12*(1+Supuestos!B21) -> 8270.5368 | E13: =E12*(1+Supuestos!B21) -> -2108.9869 | F13: =D13+E13 -> 6161.5499 | G13: =G12+F13 -> 44239.046 | H13: =H12*(1+Supuestos!B22) -> 96661.899 | I13: =I12 -> 55483.5 | J13: =(H13+G13-I13)/I13 -> 1.5395108 | K13: =F13+H13*(1-Supuestos!B4) -> 97990.354
A15: TIR 10 años | B15: =IRR(K3:K13) -> 0.11469281

Sheet Reus Trasteros 10A
A1: REUS 66m² → 11 TRASTEROS — OFERTA 22.000 €
A2: Año | B2: Fase | C2: CapEx | D2: Ingresos brutos | E2: Opex | F2: Flujo operativo neto | G2: Caja operativa acumulada | H2: Valor negocio/activo | I2: CapEx acumulado | J2: ROI económico acumulado | K2: Flujo para TIR
A3: 0 | B3: Compra + reforma | C3: =-Supuestos!B32 -> -45000 | D3: 0 | E3: 0 | F3: 0 | G3: 0 | H3: =Supuestos!B32 -> 45000 | I3: =Supuestos!B32 -> 45000 | J3: =(H3+G3-I3)/I3 -> 0 | K3: =C3 -> -45000
A4: 1 | B4: Ramp-up 50% | C4: 0 | D4: =Supuestos!B33*Supuestos!B34*12*Supuestos!B35 -> 3960 | E4: =-Supuestos!B37 -> -2040 | F4: =D4+E4 -> 1920 | G4: =F4 -> 1920 | H4: =Supuestos!B32 -> 45000 | I4: =I3 -> 45000 | J4: =(H4+G4-I4)/I4 -> 0.042666667 | K4: =F4 -> 1920
A5: 2 | B5: Ocupación 90% | C5: 0 | D5: =Supuestos!B33*Supuestos!B34*12*Supuestos!B36 -> 7128 | E5: =E4*(1+Supuestos!B39) -> -2080.8 | F5: =D5+E5 -> 5047.2 | G5: =G4+F5 -> 6967.2 | H5: =F5/Supuestos!B40 -> 56080 | I5: =I4 -> 45000 | J5: =(H5+G5-I5)/I5 -> 0.40104889 | K5: =F5 -> 5047.2
A6: 3 | B6: Estabilizado | C6: 0 | D6: =D5*(1+Supuestos!B38) -> 7270.56 | E6: =E5*(1+Supuestos!B39) -> -2122.416 | F6: =D6+E6 -> 5148.144 | G6: =G5+F6 -> 12115.344 | H6: =F6/Supuestos!B40 -> 57201.6 | I6: =I5 -> 45000 | J6: =(H6+G6-I6)/I6 -> 0.54037653 | K6: =F6 -> 5148.144
A7: 4 | B7: Estabilizado | C7: 0 | D7: =D6*(1+Supuestos!B38) -> 7415.9712 | E7: =E6*(1+Supuestos!B39) -> -2164.8643 | F7: =D7+E7 -> 5251.1069 | G7: =G6+F7 -> 17366.451 | H7: =F7/Supuestos!B40 -> 58345.632 | I7: =I6 -> 45000 | J7: =(H7+G7-I7)/I7 -> 0.68249073 | K7: =F7 -> 5251.1069
A8: 5 | B8: Estabilizado | C8: 0 | D8: =D7*(1+Supuestos!B38) -> 7564.2906 | E8: =E7*(1+Supuestos!B39) -> -2208.1616 | F8: =D8+E8 -> 5356.129 | G8: =G7+F8 -> 22722.58 | H8: =F8/Supuestos!B40 -> 59512.545 | I8: =I7 -> 45000 | J8: =(H8+G8-I8)/I8 -> 0.82744721 | K8: =F8 -> 5356.129
A9: 6 | B9: Estabilizado | C9: 0 | D9: =D8*(1+Supuestos!B38) -> 7715.5764 | E9: =E8*(1+Supuestos!B39) -> -2252.3248 | F9: =D9+E9 -> 5463.2516 | G9: =G8+F9 -> 28185.832 | H9: =F9/Supuestos!B40 -> 60702.796 | I9: =I8 -> 45000 | J9: =(H9+G9-I9)/I9 -> 0.97530282 | K9: =F9 -> 5463.2516
A10: 7 | B10: Estabilizado | C10: 0 | D10: =D9*(1+Supuestos!B38) -> 7869.888 | E10: =E9*(1+Supuestos!B39) -> -2297.3713 | F10: =D10+E10 -> 5572.5166 | G10: =G9+F10 -> 33758.348 | H10: =F10/Supuestos!B40 -> 61916.851 | I10: =I9 -> 45000 | J10: =(H10+G10-I10)/I10 -> 1.1261155 | K10: =F10 -> 5572.5166
A11: 8 | B11: Estabilizado | C11: 0 | D11: =D10*(1+Supuestos!B38) -> 8027.2857 | E11: =E10*(1+Supuestos!B39) -> -2343.3188 | F11: =D11+E11 -> 5683.967 | G11: =G10+F11 -> 39442.315 | H11: =F11/Supuestos!B40 -> 63155.188 | I11: =I10 -> 45000 | J11: =(H11+G11-I11)/I11 -> 1.2799445 | K11: =F11 -> 5683.967
A12: 9 | B12: Estabilizado | C12: 0 | D12: =D11*(1+Supuestos!B38) -> 8187.8314 | E12: =E11*(1+Supuestos!B39) -> -2390.1851 | F12: =D12+E12 -> 5797.6463 | G12: =G11+F12 -> 45239.961 | H12: =F12/Supuestos!B40 -> 64418.292 | I12: =I11 -> 45000 | J12: =(H12+G12-I12)/I12 -> 1.4368501 | K12: =F12 -> 5797.6463
A13: 10 | B13: Estabilizado | C13: 0 | D13: =D12*(1+Supuestos!B38) -> 8351.5881 | E13: =E12*(1+Supuestos!B39) -> -2437.9888 | F13: =D13+E13 -> 5913.5992 | G13: =G12+F13 -> 51153.561 | H13: =F13/Supuestos!B40 -> 65706.658 | I13: =I12 -> 45000 | J13: =(H13+G13-I13)/I13 -> 1.5968937 | K13: =F13+H13*(1-Supuestos!B41) -> 68334.924
A15: TIR 10 años | B15: =IRR(K3:K13) -> 0.12836158
A16: Nota clave | B16: El modelo anterior sobreestimaba ingresos: 11 × 70 € × 12 = 9.240 € corresponde a 100% ocupación, no 90%. Base corregida usa 60 €/mes y 90% estabilizado.

Sheet Tinamus 10A
A1: TINAMUS 25 — MODELO UNLEVERED / PROYECTO COMPLETO
A2: Año | B2: Fase | C2: CapEx | D2: Ingresos alquiler | E2: Opex | F2: Flujo operativo neto | G2: Caja operativa acumulada | H2: Valor activo | I2: CapEx acumulado | J2: ROI económico acumulado | K2: Flujo para TIR
A3: 0 | B3: Compra + puesta IT | C3: =-(Supuestos!B46+Supuestos!B47+Supuestos!B48) -> -111900 | D3: 0 | E3: 0 | F3: 0 | G3: 0 | H3: =Supuestos!B46 -> 99900 | I3: =-C3 -> 111900 | J3: =(H3+G3-I3)/I3 -> -0.10723861 | K3: =C3 -> -111900
A4: 1 | B4: IT / local | C4: 0 | D4: 0 | E4: =-Supuestos!B59 -> -1800 | F4: =D4+E4 -> -1800 | G4: =F4 -> -1800 | H4: =H3*(1+Supuestos!B54) -> 101898 | I4: =I3 -> 111900 | J4: =(H4+G4-I4)/I4 -> -0.10546917 | K4: =F4 -> -1800
A5: 2 | B5: Conversión | C5: =-Supuestos!B49 -> -32500 | D5: 0 | E5: =-Supuestos!B59 -> -1800 | F5: =D5+E5 -> -1800 | G5: =G4+F5 -> -3600 | H5: =Supuestos!B51 -> 180000 | I5: =I4-C5 -> 144400 | J5: =(H5+G5-I5)/I5 -> 0.22160665 | K5: =C5+F5 -> -34300
A6: 3 | B6: Vivienda alquilada | C6: 0 | D6: =Supuestos!B52*12 -> 11700 | E6: =-D6*Supuestos!B53 -> -3510 | F6: =D6+E6 -> 8190 | G6: =G5+F6 -> 4590 | H6: =H5*(1+Supuestos!B54) -> 183600 | I6: =I5 -> 144400 | J6: =(H6+G6-I6)/I6 -> 0.30325485 | K6: =F6 -> 8190
A7: 4 | B7: Vivienda alquilada | C7: 0 | D7: =D6*(1+Supuestos!B55) -> 11934 | E7: =E6*(1+Supuestos!B55) -> -3580.2 | F7: =D7+E7 -> 8353.8 | G7: =G6+F7 -> 12943.8 | H7: =H6*(1+Supuestos!B54) -> 187272 | I7: =I6 -> 144400 | J7: =(H7+G7-I7)/I7 -> 0.38653601 | K7: =F7 -> 8353.8
A8: 5 | B8: Vivienda alquilada | C8: 0 | D8: =D7*(1+Supuestos!B55) -> 12172.68 | E8: =E7*(1+Supuestos!B55) -> -3651.804 | F8: =D8+E8 -> 8520.876 | G8: =G7+F8 -> 21464.676 | H8: =H7*(1+Supuestos!B54) -> 191017.44 | I8: =I7 -> 144400 | J8: =(H8+G8-I8)/I8 -> 0.4714828 | K8: =F8 -> 8520.876
A9: 6 | B9: Vivienda alquilada | C9: 0 | D9: =D8*(1+Supuestos!B55) -> 12416.134 | E9: =E8*(1+Supuestos!B55) -> -3724.8401 | F9: =D9+E9 -> 8691.2935 | G9: =G8+F9 -> 30155.97 | H9: =H8*(1+Supuestos!B54) -> 194837.79 | I9: =I8 -> 144400 | J9: =(H9+G9-I9)/I9 -> 0.55812852 | K9: =F9 -> 8691.2935
A10: 7 | B10: Vivienda alquilada | C10: 0 | D10: =D9*(1+Supuestos!B55) -> 12664.456 | E10: =E9*(1+Supuestos!B55) -> -3799.3369 | F10: =D10+E10 -> 8865.1194 | G10: =G9+F10 -> 39021.089 | H10: =H9*(1+Supuestos!B54) -> 198734.54 | I10: =I9 -> 144400 | J10: =(H10+G10-I10)/I10 -> 0.64650716 | K10: =F10 -> 8865.1194
A11: 8 | B11: Vivienda alquilada | C11: 0 | D11: =D10*(1+Supuestos!B55) -> 12917.745 | E11: =E10*(1+Supuestos!B55) -> -3875.3236 | F11: =D11+E11 -> 9042.4218 | G11: =G10+F11 -> 48063.511 | H11: =H10*(1+Supuestos!B54) -> 202709.24 | I11: =I10 -> 144400 | J11: =(H11+G11-I11)/I11 -> 0.73665337 | K11: =F11 -> 9042.4218
A12: 9 | B12: Vivienda alquilada | C12: 0 | D12: =D11*(1+Supuestos!B55) -> 13176.1 | E12: =E11*(1+Supuestos!B55) -> -3952.8301 | F12: =D12+E12 -> 9223.2702 | G12: =G11+F12 -> 57286.781 | H12: =H11*(1+Supuestos!B54) -> 206763.42 | I12: =I11 -> 144400 | J12: =(H12+G12-I12)/I12 -> 0.8286025 | K12: =F12 -> 9223.2702
A13: 10 | B13: Vivienda alquilada | C13: 0 | D13: =D12*(1+Supuestos!B55) -> 13439.622 | E13: =E12*(1+Supuestos!B55) -> -4031.8867 | F13: =D13+E13 -> 9407.7356 | G13: =G12+F13 -> 66694.517 | H13: =H12*(1+Supuestos!B54) -> 210898.69 | I13: =I12 -> 144400 | J13: =(H13+G13-I13)/I13 -> 0.92239062 | K13: =F13+H13*(1-Supuestos!B4) -> 209761.49
A15: TIR proyecto sin deuda | B15: =IRR(K3:K13) -> 0.073345255
A16: Nota | B16: Comparación homogénea: se incluye compra, reforma futura y costes pre-conversión. La rentabilidad sobre solo 38-42k de equity sería mayor únicamente si el resto lo financian deuda/beneficios IT.

Sheet Vehiculos 10A
A1: VEHÍCULOS — PROYECCIÓN 10 AÑOS
A2: Año | B2: L3H2 flujo neto | C2: L3H2 acumulado | D2: L3H2 valor residual | E2: Camper flujo neto | F2: Camper acumulado | G2: Camper valor residual
A3: 0 | B3: =-Supuestos!B63 -> -45000 | C3: 0 | D3: 0 | E3: =-Supuestos!B66 -> -45000 | F3: 0 | G3: 0
A4: 1 | B4: =Supuestos!B64 -> 10720 | C4: =B4 -> 10720 | D4: 0 | E4: =Supuestos!B67 -> 5730 | F4: =E4 -> 5730 | G4: 0
A5: 2 | B5: =Supuestos!B64 -> 10720 | C5: =C4+B5 -> 21440 | D5: 0 | E5: =Supuestos!B67 -> 5730 | F5: =F4+E5 -> 11460 | G5: 0
A6: 3 | B6: =Supuestos!B64 -> 10720 | C6: =C5+B6 -> 32160 | D6: 0 | E6: =Supuestos!B67 -> 5730 | F6: =F5+E6 -> 17190 | G6: 0
A7: 4 | B7: =Supuestos!B64 -> 10720 | C7: =C6+B7 -> 42880 | D7: 0 | E7: =Supuestos!B67 -> 5730 | F7: =F6+E7 -> 22920 | G7: 0
A8: 5 | B8: =Supuestos!B64 -> 10720 | C8: =C7+B8 -> 53600 | D8: 0 | E8: =Supuestos!B67 -> 5730 | F8: =F7+E8 -> 28650 | G8: 0
A9: 6 | B9: =Supuestos!B64 -> 10720 | C9: =C8+B9 -> 64320 | D9: 0 | E9: =Supuestos!B67 -> 5730 | F9: =F8+E9 -> 34380 | G9: 0
A10: 7 | B10: =Supuestos!B64 -> 10720 | C10: =C9+B10 -> 75040 | D10: 0 | E10: =Supuestos!B67 -> 5730 | F10: =F9+E10 -> 40110 | G10: 0
A11: 8 | B11: =Supuestos!B64 -> 10720 | C11: =C10+B11 -> 85760 | D11: 0 | E11: =Supuestos!B67 -> 5730 | F11: =F10+E11 -> 45840 | G11: 0
A12: 9 | B12: =Supuestos!B64 -> 10720 | C12: =C11+B12 -> 96480 | D12: 0 | E12: =Supuestos!B67 -> 5730 | F12: =F11+E12 -> 51570 | G12: 0
A13: 10 | B13: =Supuestos!B64+Supuestos!B65 -> 19492 | C13: =C12+Supuestos!B64 -> 107200 | D13: =Supuestos!B65 -> 8772 | E13: =Supuestos!B67+Supuestos!B68 -> 16880 | F13: =F12+Supuestos!B67 -> 57300 | G13: =Supuestos!B68 -> 11150
A15: TIR L3H2 | B15: =IRR(B3:B13) -> 0.20848185
A16: TIR Camper | B16: =IRR(E3:E13) -> 0.073878783
